<?xml version="1.0" ?>
<!-- =================================================================================== -->
<!-- |    This document was autogenerated by xacro from ssmm_gazebo.urdf.xacro         | -->
<!-- |    EDITING THIS FILE BY HAND IS NOT RECOMMENDED                                 | -->
<!-- =================================================================================== -->
<!-- This URDF was automatically created by SolidWorks to URDF Exporter! Originally created by Stephen Brawner (brawner@gmail.com) 
     Commit Version: 1.5.1-0-g916b5db  Build Version: 1.5.7152.31018
     For more information, please see http://wiki.ros.org/sw_urdf_exporter -->
<robot name="ssmm_gazebo">
  <!-- diff_drive controller -->
  <gazebo>
    <plugin filename="libgazebo_ros_diff_drive.so" name="diff_drive">
      <ros>
        <namespace>/ssmm_gazebo</namespace>
      </ros>
      <!-- wheels -->
      <left_joint>base_to_lw</left_joint>
      <right_joint>base_to_rw</right_joint>
      <!-- kinematics -->
      <wheel_separation>0.4</wheel_separation>
      <wheel_diameter>0.2</wheel_diameter>
      <!-- limits -->
      <max_wheel_torque>10</max_wheel_torque>
      <max_wheel_acceleration>1.0</max_wheel_acceleration>
      <!-- output -->
      <publish_odom>true</publish_odom>
      <publish_odom_tf>true</publish_odom_tf>
      <publish_wheel_tf>true</publish_wheel_tf>
      <odometry_frame>odom</odometry_frame>
      <robot_base_frame>robot_footprint</robot_base_frame>
    </plugin>
  </gazebo>
  <gazebo reference="laser">
    <sensor name="head_rplidar_sensor" type="ray">
      <pose>0 0 0.06 0 0 0</pose>
      <visualize>false</visualize>
      <update_rate>40</update_rate>
      <ray>
        <scan>
          <horizontal>
            <samples>720</samples>
            <resolution>1</resolution>
            <min_angle>-3.14159265</min_angle>
            <max_angle>3.14159265</max_angle>
          </horizontal>
        </scan>
        <range>
          <min>0.2</min>
          <max>12.0</max>
          <resolution>0.01</resolution>
        </range>
        <noise>
          <type>gaussian</type>
          <mean>0.0</mean>
          <stddev>0.01</stddev>
        </noise>
      </ray>
      <plugin filename="libgazebo_ros_laser.so" name="gazebo_ros_head_rplidar_controller">
        <topicName>scan</topicName>
        <frameName>laser</frameName>
      </plugin>
    </sensor>
  </gazebo>
  <link name="base_link">
    <inertial>
      <origin rpy="0 0 0" xyz="0.0054761 0.046718 -0.00077332"/>
      <mass value="2.2263"/>
      <inertia ixx="0.021054" ixy="1.5769E-06" ixz="-0.00021664" iyy="0.036188" iyz="-7.2302E-08" izz="0.016028"/>
    </inertial>
    <visual>
      <origin rpy="1.5708 0 0" xyz="0 0 0"/>
      <geometry>
        <mesh filename="file:///home/benlee/ros2_ws/install/ssmm_gazebo/share/ssmm_gazebo/meshes/base_link.STL" scale="1 1 1"/>
      </geometry>
      <material name="">
        <color rgba="0.75294 0.75294 0.75294 1"/>
      </material>
    </visual>
    <collision>
      <origin rpy="1.5708  0 0" xyz="0 0 0"/>
      <geometry>
        <mesh filename="file:///home/benlee/ros2_ws/install/ssmm_gazebo/share/ssmm_gazebo/meshes/base_link.STL" scale="1 1 1"/>
      </geometry>
    </collision>
  </link>
  <link name="right_wheel">
    <inertial>
      <origin rpy="0 0 0" xyz="0 1.7347E-18 0"/>
      <mass value="0.1112"/>
      <inertia ixx="5.5328E-05" ixy="-1.0735E-21" ixz="-3.2923E-19" iyy="5.5328E-05" iyz="-2.9102E-21" izz="0.00010246"/>
    </inertial>
    <visual>
      <origin rpy="0 0 0" xyz="0 0 0"/>
      <geometry>
        <mesh filename="file:///home/benlee/ros2_ws/install/ssmm_gazebo/share/ssmm_gazebo/meshes/right_wheel.STL"/>
      </geometry>
      <material name="">
        <color rgba="0.75294 0.75294 0.75294 1"/>
      </material>
    </visual>
    <collision>
      <origin rpy="0 0 0" xyz="0 0 0"/>
      <geometry>
        <mesh filename="file:///home/benlee/ros2_ws/install/ssmm_gazebo/share/ssmm_gazebo/meshes/right_wheel.STL"/>
      </geometry>
    </collision>
  </link>
  <joint name="base_to_rw" type="continuous">
    <origin rpy="1.5708 0 0" xyz="0.10789 -0.175 0.025"/>
    <parent link="base_link"/>
    <child link="right_wheel"/>
    <axis xyz="0 0 1"/>
  </joint>
  <link name="left_wheel">
    <inertial>
      <origin rpy="0 0 0" xyz="-2.9803E-14 -2.681E-14 1.5599E-14"/>
      <mass value="0.1112"/>
      <inertia ixx="5.5328E-05" ixy="-1.3032E-22" ixz="-4.1548E-19" iyy="5.5328E-05" iyz="-1.6842E-19" izz="0.00010246"/>
    </inertial>
    <visual>
      <origin rpy="0 0 0" xyz="0 0 0"/>
      <geometry>
        <mesh filename="file:///home/benlee/ros2_ws/install/ssmm_gazebo/share/ssmm_gazebo/meshes/left_wheel.STL"/>
      </geometry>
      <material name="">
        <color rgba="0.75294 0.75294 0.75294 1"/>
      </material>
    </visual>
    <collision>
      <origin rpy="0 0 0" xyz="0 0 0"/>
      <geometry>
        <mesh filename="file:///home/benlee/ros2_ws/install/ssmm_gazebo/share/ssmm_gazebo/meshes/left_wheel.STL"/>
      </geometry>
    </collision>
  </link>
  <joint name="base_to_lw" type="continuous">
    <origin rpy="1.5708 0 3.1416" xyz="0.10789 0.175 0.025"/>
    <parent link="base_link"/>
    <child link="left_wheel"/>
    <axis xyz="0 0 1"/>
  </joint>
  <link name="lidar">
    <inertial>
      <origin rpy="0 0 0" xyz="0 0 0"/>
      <mass value="0"/>
      <inertia ixx="0" ixy="0" ixz="0" iyy="0" iyz="0" izz="0"/>
    </inertial>
    <visual>
      <origin rpy="0 0 0" xyz="0 0 0"/>
      <geometry>
        <mesh filename="file:///home/benlee/ros2_ws/install/ssmm_gazebo/share/ssmm_gazebo/meshes/lidar.STL"/>
      </geometry>
      <material name="">
        <color rgba="1 1 1 1"/>
      </material>
    </visual>
    <collision>
      <origin rpy="0 0 0" xyz="0 0 0"/>
      <geometry>
        <mesh filename="file:///home/benlee/ros2_ws/install/ssmm_gazebo/share/ssmm_gazebo/meshes/lidar.STL"/>
      </geometry>
    </collision>
  </link>
  <joint name="base_to_lidar" type="fixed">
    <origin rpy="1.5708 0 0" xyz="0.097808 -0.0015 0.13"/>
    <parent link="base_link"/>
    <child link="lidar"/>
    <axis xyz="0 0 0"/>
  </joint>
</robot>
