<?xml version="1.0" encoding="utf-8"?>
<!-- This URDF was automatically created by SolidWorks to URDF Exporter! Originally created by Stephen Brawner (brawner@gmail.com) 
     Commit Version: 1.5.1-0-g916b5db  Build Version: 1.5.7152.31018
     For more information, please see http://wiki.ros.org/sw_urdf_exporter -->
<robot
  name="ssmm_gazebo">
  <link
    name="base_link">
    <inertial>
      <origin
        xyz="0.0054761 0.046718 -0.00077332"
        rpy="0 0 0" />
      <mass
        value="2.2263" />
      <inertia
        ixx="0.021054"
        ixy="1.5769E-06"
        ixz="-0.00021664"
        iyy="0.036188"
        iyz="-7.2302E-08"
        izz="0.016028" />
    </inertial>
    <visual>
      <origin
        xyz="0 0 0"
        rpy="1.5708 0 0" />
      <geometry>
        <mesh filename="file://$(find ssmm_gazebo)/meshes/base_link.STL" scale = "1 1 1"/>
      </geometry>
      <material
        name="">
        <color
          rgba="0.75294 0.75294 0.75294 1" />
      </material>
    </visual>
    <collision>
      <origin
        xyz="0 0 0"
        rpy="1.5708  0 0" />
      <geometry>
        <mesh
          filename="file://$(find ssmm_gazebo)/meshes/base_link.STL" scale = "1 1 1"/>
      </geometry>
    </collision>
  </link>
  <link
    name="right_wheel">
    <inertial>
      <origin
        xyz="0 1.7347E-18 0"
        rpy="0 0 0" />
      <mass
        value="0.1112" />
      <inertia
        ixx="5.5328E-05"
        ixy="-1.0735E-21"
        ixz="-3.2923E-19"
        iyy="5.5328E-05"
        iyz="-2.9102E-21"
        izz="0.00010246" />
    </inertial>
    <visual>
      <origin
        xyz="0 0 0"
        rpy="0 0 0" />
      <geometry>
        <mesh
          filename="file://$(find ssmm_gazebo)/meshes/right_wheel.STL" />
      </geometry>
      <material
        name="">
        <color
          rgba="0.75294 0.75294 0.75294 1" />
      </material>
    </visual>
    <collision>
      <origin
        xyz="0 0 0"
        rpy="0 0 0" />
      <geometry>
        <mesh
          filename="file://$(find ssmm_gazebo)/meshes/right_wheel.STL" />
      </geometry>
    </collision>
  </link>
  <joint
    name="base_to_rw"
    type="continuous">
    <origin
      xyz="0.10789 -0.175 0.025"
      rpy="1.5708 0 0" />
    <parent
      link="base_link" />
    <child
      link="right_wheel" />
    <axis
      xyz="0 0 1" />
  </joint>
  <link
    name="left_wheel">
    <inertial>
      <origin
        xyz="-2.9803E-14 -2.681E-14 1.5599E-14"
        rpy="0 0 0" />
      <mass
        value="0.1112" />
      <inertia
        ixx="5.5328E-05"
        ixy="-1.3032E-22"
        ixz="-4.1548E-19"
        iyy="5.5328E-05"
        iyz="-1.6842E-19"
        izz="0.00010246" />
    </inertial>
    <visual>
      <origin
        xyz="0 0 0"
        rpy="0 0 0" />
      <geometry>
        <mesh
          filename="file://$(find ssmm_gazebo)/meshes/left_wheel.STL" />
      </geometry>
      <material
        name="">
        <color
          rgba="0.75294 0.75294 0.75294 1" />
      </material>
    </visual>
    <collision>
      <origin
        xyz="0 0 0"
        rpy="0 0 0" />
      <geometry>
        <mesh
          filename="file://$(find ssmm_gazebo)/meshes/left_wheel.STL" />
      </geometry>
    </collision>
  </link>
  <joint
    name="base_to_lw"
    type="continuous">
    <origin
      xyz="0.10789 0.175 0.025"
      rpy="1.5708 0 3.1416" />
    <parent
      link="base_link" />
    <child
      link="left_wheel" />
    <axis
      xyz="0 0 1" />
  </joint>
  <link
    name="lidar">
    <inertial>
      <origin
        xyz="0 0 0"
        rpy="0 0 0" />
      <mass
        value="0" />
      <inertia
        ixx="0"
        ixy="0"
        ixz="0"
        iyy="0"
        iyz="0"
        izz="0" />
    </inertial>
    <visual>
      <origin
        xyz="0 0 0"
        rpy="0 0 0" />
      <geometry>
        <mesh
          filename="file://$(find ssmm_gazebo)/meshes/lidar.STL" />
      </geometry>
      <material
        name="">
        <color
          rgba="1 1 1 1" />
      </material>
    </visual>
    <collision>
      <origin
        xyz="0 0 0"
        rpy="0 0 0" />
      <geometry>
        <mesh
          filename="file://$(find ssmm_gazebo)/meshes/lidar.STL" />
      </geometry>
    </collision>
  </link>
  <joint
    name="base_to_lidar"
    type="fixed">
    <origin
      xyz="0.097808 -0.0015 0.13"
      rpy="1.5708 0 0" />
    <parent
      link="base_link" />
    <child
      link="lidar" />
    <axis
      xyz="0 0 0" />
  </joint>
</robot>