<?xml version="1.0" encoding="utf-8"?>
<!-- This URDF was automatically created by SolidWorks to URDF Exporter! Originally created by Stephen Brawner (brawner@gmail.com) 
     Commit Version: 1.5.1-0-g916b5db  Build Version: 1.5.7152.31018
     For more information, please see http://wiki.ros.org/sw_urdf_exporter -->
<robot
  name="ssmm_gazebo">
  <link
    name="base_link">
    <inertial>
      <origin
        xyz="0.043579 -0.017838 -0.022157"
        rpy="0 0 0" />
      <mass
        value="0.8861" />
      <inertia
        ixx="0.0079901"
        ixy="1.1902E-06"
        ixz="-1.0289E-18"
        iyy="0.016382"
        iyz="-4.3652E-19"
        izz="0.0084009" />
    </inertial>
    <visual>
      <origin
        xyz="0 0 0"
        rpy="0 0 0" />
      <geometry>
        <mesh
          filename="package://ssmm_gazebo/meshes/base_link.STL" />
      </geometry>
      <material
        name="">
        <color
          rgba="0.75294 0.75294 0.75294 1" />
      </material>
    </visual>
    <collision>
      <origin
        xyz="0 0 0"
        rpy="0 0 0" />
      <geometry>
        <mesh
          filename="package://ssmm_gazebo/meshes/base_link.STL" />
      </geometry>
    </collision>
  </link>
  <link
    name="right_wheel">
    <inertial>
      <origin
        xyz="0.12573 0.19245 0.13898"
        rpy="0 0 0" />
      <mass
        value="0.11659" />
      <inertia
        ixx="5.5634E-05"
        ixy="-6.5495E-10"
        ixz="-1.1058E-09"
        iyy="5.5634E-05"
        iyz="6.7403E-10"
        izz="0.00010273" />
    </inertial>
    <visual>
      <origin
        xyz="0 0 0"
        rpy="0 0 0" />
      <geometry>
        <mesh
          filename="package://ssmm_gazebo/meshes/right_wheel.STL" />
      </geometry>
      <material
        name="">
        <color
          rgba="0.75294 0.75294 0.75294 1" />
      </material>
    </visual>
    <collision>
      <origin
        xyz="0 0 0"
        rpy="0 0 0" />
      <geometry>
        <mesh
          filename="package://ssmm_gazebo/meshes/right_wheel.STL" />
      </geometry>
    </collision>
  </link>
  <joint
    name="base_to_rw"
    type="continuous">
    <origin
      xyz="0.10602 -0.183 0.022"
      rpy="1.5708 0 0" />
    <parent
      link="base_link" />
    <child
      link="right_wheel" />
    <axis
      xyz="0 0 1" />
  </joint>
  <link
    name="left_wheel">
    <inertial>
      <origin
        xyz="-0.12573 0.19245 0.13898"
        rpy="0 0 0" />
      <mass
        value="0.11659" />
      <inertia
        ixx="5.5634E-05"
        ixy="6.9199E-10"
        ixz="-1.0614E-09"
        iyy="5.5634E-05"
        iyz="-7.4188E-10"
        izz="0.00010273" />
    </inertial>
    <visual>
      <origin
        xyz="0 0 0"
        rpy="0 0 0" />
      <geometry>
        <mesh
          filename="package://ssmm_gazebo/meshes/left_wheel.STL" />
      </geometry>
      <material
        name="">
        <color
          rgba="0.75294 0.75294 0.75294 1" />
      </material>
    </visual>
    <collision>
      <origin
        xyz="0 0 0"
        rpy="0 0 0" />
      <geometry>
        <mesh
          filename="package://ssmm_gazebo/meshes/left_wheel.STL" />
      </geometry>
    </collision>
  </link>
  <joint
    name="base_to_lw"
    type="continuous">
    <origin
      xyz="0.10602 0.183 0.022"
      rpy="-1.5708 0 0" />
    <parent
      link="base_link" />
    <child
      link="left_wheel" />
    <axis
      xyz="0 0 1" />
  </joint>
  <link
    name="lidar">
    <inertial>
      <origin
        xyz="-0.13583 -0.060836 -0.10229"
        rpy="0 0 0" />
      <mass
        value="0.16306" />
      <inertia
        ixx="6.0724E-05"
        ixy="4.1104E-08"
        ixz="2.464E-07"
        iyy="9.2342E-05"
        iyz="6.7628E-08"
        izz="7.5686E-05" />
    </inertial>
    <visual>
      <origin
        xyz="0 0 0"
        rpy="0 0 0" />
      <geometry>
        <mesh
          filename="package://ssmm_gazebo/meshes/lidar.STL" />
      </geometry>
      <material
        name="">
        <color
          rgba="0.75294 0.75294 0.75294 1" />
      </material>
    </visual>
    <collision>
      <origin
        xyz="0 0 0"
        rpy="0 0 0" />
      <geometry>
        <mesh
          filename="package://ssmm_gazebo/meshes/lidar.STL" />
      </geometry>
    </collision>
  </link>
  <joint
    name="base_to_lidar"
    type="fixed">
    <origin
      xyz="0.10202 0 0.1339"
      rpy="0 0 0" />
    <parent
      link="base_link" />
    <child
      link="lidar" />
    <axis
      xyz="0 0 0" />
  </joint>
</robot>