<?xml version="1.0" encoding="utf-8"?>
<!-- This URDF was automatically created by SolidWorks to URDF Exporter! Originally created by Stephen Brawner (brawner@gmail.com) 
     Commit Version: 1.5.1-0-g916b5db  Build Version: 1.5.7152.31018
     For more information, please see http://wiki.ros.org/sw_urdf_exporter -->
<robot name="ssmm_robot" xmlns:xacro="http://www.ros.org/wiki/xacro">
  <xacro:include filename="$(find ssmm_robot)/urdf/ssmm_robot.gazebo"/>
  <link
    name="base_link">
    <inertial>
      <origin
        xyz="-0.069584 -0.024502 0.44053"
        rpy="0 0 0" />
      <mass
        value="6.3015" />
      <inertia
        ixx="0.55585"
        ixy="0.00023242"
        ixz="6.1801E-06"
        iyy="0.55093"
        iyz="-1.7166E-05"
        izz="0.039134" />
    </inertial>
    <visual>
      <origin
        xyz="0 0 0"
        rpy="0 0 0" />
      <geometry>
        <mesh
          filename="file://$(find ssmm_robot)/meshes/base_link.STL" />
      </geometry>
      <material
        name="">
        <color
          rgba="0.75294 0.75294 0.75294 1" />
      </material>
    </visual>
    <collision>
      <origin
        xyz="0 0 0"
        rpy="0 0 0" />
      <geometry>
        <mesh
          filename="file://$(find ssmm_robot)/meshes/base_link.STL" />
      </geometry>
    </collision>
  </link>
  <link
    name="right_wheel">
    <inertial>
      <origin
        xyz="1.3878E-17 0 2.7756E-17"
        rpy="0 0 0" />
      <mass
        value="0.1112" />
      <inertia
        ixx="5.5328E-05"
        ixy="-5.4445E-21"
        ixz="7.4306E-19"
        iyy="5.5328E-05"
        iyz="-2.0017E-21"
        izz="0.00010246" />
    </inertial>
    <visual>
      <origin
        xyz="0 0 0"
        rpy="0 0 0" />
      <geometry>
        <mesh
          filename="file://$(find ssmm_robot)/meshes/right_wheel.STL" />
      </geometry>
      <material
        name="">
        <color
          rgba="0.75294 0.75294 0.75294 1" />
      </material>
    </visual>
    <collision>
      <origin
        xyz="0 0 0"
        rpy="0 0 0" />
      <geometry>
        <mesh
          filename="file://$(find ssmm_robot)/meshes/right_wheel.STL" />
      </geometry>
    </collision>
  </link>
  <joint
    name="base_to_rw"
    type="continuous">
    <origin
      xyz="0.10789 -0.184 0.014"
      rpy="-1.5708 0 -3.1416" />
    <parent
      link="base_link" />
    <child
      link="right_wheel" />
    <axis
      xyz="0 0 1" />
  </joint>
  <link
    name="left_wheel">
    <inertial>
      <origin
        xyz="0 -3.4694E-18 5.5511E-17"
        rpy="0 0 0" />
      <mass
        value="0.1112" />
      <inertia
        ixx="5.5328E-05"
        ixy="-3.0502E-21"
        ixz="-6.2283E-19"
        iyy="5.5328E-05"
        iyz="-3.8342E-21"
        izz="0.00010246" />
    </inertial>
    <visual>
      <origin
        xyz="0 0 0"
        rpy="0 0 0" />
      <geometry>
        <mesh
          filename="file://$(find ssmm_robot)/meshes/left_wheel.STL" />
      </geometry>
      <material
        name="">
        <color
          rgba="0.75294 0.75294 0.75294 1" />
      </material>
    </visual>
    <collision>
      <origin
        xyz="0 0 0"
        rpy="0 0 0" />
      <geometry>
        <mesh
          filename="file://$(find ssmm_robot)/meshes/left_wheel.STL" />
      </geometry>
    </collision>
  </link>
  <joint
    name="base_to_lw"
    type="continuous">
    <origin
      xyz="0.10789 0.184 0.014"
      rpy="1.5708 0 3.1416" />
    <parent
      link="base_link" />
    <child
      link="left_wheel" />
    <axis
      xyz="0 0 1" />
  </joint>
  <link
    name="lidar">
    <inertial>
      <origin
        xyz="-0.00093409 -0.00025709 0.0097851"
        rpy="0 0 0" />
      <mass
        value="0.16306" />
      <inertia
        ixx="6.0726E-05"
        ixy="1.1E-07"
        ixz="-2.3221E-07"
        iyy="6.0437E-05"
        iyz="-6.5607E-08"
        izz="0.00010759" />
    </inertial>
    <visual>
      <origin
        xyz="0 0 0"
        rpy="0 0 0" />
      <geometry>
        <mesh
          filename="file://$(find ssmm_robot)/meshes/lidar.STL" />
      </geometry>
      <material
        name="">
        <color
          rgba="0.75294 0.75294 0.75294 1" />
      </material>
    </visual>
    <collision>
      <origin
        xyz="0 0 0"
        rpy="0 0 0" />
      <geometry>
        <mesh
          filename="file://$(find ssmm_robot)/meshes/lidar.STL" />
      </geometry>
    </collision>
  </link>
  <joint
    name="base_to_lidar"
    type="fixed">
    <origin
      xyz="0.10389 0 0.1153"
      rpy="0 0 0" />
    <parent
      link="base_link" />
    <child
      link="lidar" />
    <axis
      xyz="0 0 0" />
  </joint>
  <link
    name="caster">
    <inertial>
      <origin
        xyz="8.1068E-08 -9.9573E-09 0.010191"
        rpy="0 0 0" />
      <mass
        value="0.010413" />
      <inertia
        ixx="8.069E-07"
        ixy="-1.1282E-11"
        ixz="-6.6095E-12"
        iyy="7.4592E-07"
        iyz="1.0936E-11"
        izz="1.0475E-06" />
    </inertial>
    <visual>
      <origin
        xyz="0 0 0"
        rpy="0 0 0" />
      <geometry>
        <mesh
          filename="file://$(find ssmm_robot)/meshes/caster.STL" />
      </geometry>
      <material
        name="">
        <color
          rgba="0.75294 0.75294 0.75294 1" />
      </material>
    </visual>
    <collision>
      <origin
        xyz="0 0 0"
        rpy="0 0 0" />
      <geometry>
        <mesh
          filename="file://$(find ssmm_robot)/meshes/caster.STL" />
      </geometry>
    </collision>
  </link>
  <joint
    name="base_to_caster"
    type="fixed">
    <origin
      xyz="-0.10811 0 -0.026223"
      rpy="0 0 0" />
    <parent
      link="base_link" />
    <child
      link="caster" />
    <axis
      xyz="0 0 0" />
  </joint>
  <!-- <link
    name="link1">
    <inertial>
      <origin
        xyz="0.22093 0.011504 0.0090405"
        rpy="0 0 0" />
      <mass
        value="0.54731" />
      <inertia
        ixx="0.00022972"
        ixy="1.4914E-05"
        ixz="6.8464E-05"
        iyy="0.0067795"
        iyz="-1.3457E-07"
        izz="0.0067204" />
    </inertial>
    <visual>
      <origin
        xyz="0 0 0"
        rpy="0 0 0" />
      <geometry>
        <mesh
          filename="file://$(find ssmm_robot)/meshes/link1.STL" />
      </geometry>
      <material
        name="">
        <color
          rgba="0.75294 0.75294 0.75294 1" />
      </material>
    </visual>
    <collision>
      <origin
        xyz="0 0 0"
        rpy="0 0 0" />
      <geometry>
        <mesh
          filename="file://$(find ssmm_robot)/meshes/link1.STL" />
      </geometry>
    </collision>
  </link>
  <joint
    name="base_to_link1"
    type="prismatic">
    <origin
      xyz="-0.13891 -0.0395 0.20287"
      rpy="0 0 0" />
    <parent
      link="base_link" />
    <child
      link="link1" />
    <axis
      xyz="0 0 0" />
    <limit
      lower="0"
      upper="0"
      effort="0"
      velocity="0" />
  </joint>
  <link
    name="link2">
    <inertial>
      <origin
        xyz="0.2443 0.0075105 -0.0095405"
        rpy="0 0 0" />
      <mass
        value="0.19489" />
      <inertia
        ixx="5.3126E-05"
        ixy="-1.1309E-08"
        ixz="-1.3915E-06"
        iyy="0.00093988"
        iyz="1.424E-08"
        izz="0.00095549" />
    </inertial>
    <visual>
      <origin
        xyz="0 0 0"
        rpy="0 0 0" />
      <geometry>
        <mesh
          filename="file://$(find ssmm_robot)/meshes/link2.STL" />
      </geometry>
      <material
        name="">
        <color
          rgba="0.75294 0.75294 0.75294 1" />
      </material>
    </visual>
    <collision>
      <origin
        xyz="0 0 0"
        rpy="0 0 0" />
      <geometry>
        <mesh
          filename="file://$(find ssmm_robot)/meshes/link2.STL" />
      </geometry>
    </collision>
  </link>
  <joint
    name="link1_to_link2"
    type="prismatic">
    <origin
      xyz="0.16921 0.0066 0.06353"
      rpy="0 0 0" />
    <parent
      link="link1" />
    <child
      link="link2" />
    <axis
      xyz="0 0 0" />
    <limit
      lower="0"
      upper="0"
      effort="0"
      velocity="0" />
  </joint>
  <link
    name="link3">
    <inertial>
      <origin
        xyz="-0.0027211 -1.9148E-05 0.044864"
        rpy="0 0 0" />
      <mass
        value="0.19674" />
      <inertia
        ixx="7.3224E-05"
        ixy="8.1145E-08"
        ixz="-2.417E-06"
        iyy="0.00010023"
        iyz="-2.1626E-08"
        izz="0.00010439" />
    </inertial>
    <visual>
      <origin
        xyz="0 0 0"
        rpy="0 0 0" />
      <geometry>
        <mesh
          filename="file://$(find ssmm_robot)/meshes/link3.STL" />
      </geometry>
      <material
        name="">
        <color
          rgba="0.75294 0.75294 0.75294 1" />
      </material>
    </visual>
    <collision>
      <origin
        xyz="0 0 0"
        rpy="0 0 0" />
      <geometry>
        <mesh
          filename="file://$(find ssmm_robot)/meshes/link3.STL" />
      </geometry>
    </collision>
  </link>
  <joint
    name="link2_to_link3"
    type="revolute">
    <origin
      xyz="0.4216 0.0079 -0.0018"
      rpy="1.5708 0 1.5598" />
    <parent
      link="link2" />
    <child
      link="link3" />
    <axis
      xyz="0 0 0" />
    <limit
      lower="0"
      upper="0"
      effort="0"
      velocity="0" />
  </joint>
  <link
    name="left_finger">
    <inertial>
      <origin
        xyz="0.030274 0.0023619 0.051097"
        rpy="0 0 0" />
      <mass
        value="0.0015302" />
      <inertia
        ixx="9.8229E-08"
        ixy="-9.494E-09"
        ixz="9.604E-09"
        iyy="7.8106E-08"
        iyz="2.0836E-08"
        izz="4.5697E-08" />
    </inertial>
    <visual>
      <origin
        xyz="0 0 0"
        rpy="0 0 0" />
      <geometry>
        <mesh
          filename="file://$(find ssmm_robot)/meshes/left_finger.STL" />
      </geometry>
      <material
        name="">
        <color
          rgba="0.75294 0.75294 0.75294 1" />
      </material>
    </visual>
    <collision>
      <origin
        xyz="0 0 0"
        rpy="0 0 0" />
      <geometry>
        <mesh
          filename="file://$(find ssmm_robot)/meshes/left_finger.STL" />
      </geometry>
    </collision>
  </link>
  <joint
    name="link3_to_lf"
    type="prismatic">
    <origin
      xyz="0.0005073 0 0.045997"
      rpy="0 0 0" />
    <parent
      link="link3" />
    <child
      link="left_finger" />
    <axis
      xyz="0 0 0" />
    <limit
      lower="0"
      upper="0"
      effort="0"
      velocity="0" />
  </joint>
  <link
    name="cam_link1">
    <inertial>
      <origin
        xyz="-9.8107E-11 0.011574 -0.021565"
        rpy="0 0 0" />
      <mass
        value="0.061567" />
      <inertia
        ixx="1.7372E-05"
        ixy="5.399E-15"
        ixz="-5.9053E-14"
        iyy="1.2032E-05"
        iyz="1.5743E-07"
        izz="1.8633E-05" />
    </inertial>
    <visual>
      <origin
        xyz="0 0 0"
        rpy="0 0 0" />
      <geometry>
        <mesh
          filename="file://$(find ssmm_robot)/meshes/cam_link1.STL" />
      </geometry>
      <material
        name="">
        <color
          rgba="0.75294 0.75294 0.75294 1" />
      </material>
    </visual>
    <collision>
      <origin
        xyz="0 0 0"
        rpy="0 0 0" />
      <geometry>
        <mesh
          filename="file://$(find ssmm_robot)/meshes/cam_link1.STL" />
      </geometry>
    </collision>
  </link>
  <joint
    name="base_to_cam_motor1"
    type="fixed">
    <origin
      xyz="0.0013904 -0.0225 1.3186"
      rpy="3.1416 0 0" />
    <parent
      link="base_link" />
    <child
      link="cam_link1" />
    <axis
      xyz="0 0 0" />
  </joint>
  <link
    name="cam_link2">
    <inertial>
      <origin
        xyz="-1.1108E-10 0.00031527 0.026226"
        rpy="0 0 0" />
      <mass
        value="0.054378" />
      <inertia
        ixx="1.3776E-05"
        ixy="-5.9147E-14"
        ixz="-5.3721E-15"
        iyy="1.3009E-05"
        iyz="-1.5619E-08"
        izz="1.0217E-05" />
    </inertial>
    <visual>
      <origin
        xyz="0 0 0"
        rpy="0 0 0" />
      <geometry>
        <mesh
          filename="file://$(find ssmm_robot)/meshes/cam_link2.STL" />
      </geometry>
      <material
        name="">
        <color
          rgba="0.75294 0.75294 0.75294 1" />
      </material>
    </visual>
    <collision>
      <origin
        xyz="0 0 0"
        rpy="0 0 0" />
      <geometry>
        <mesh
          filename="file://$(find ssmm_robot)/meshes/cam_link2.STL" />
      </geometry>
    </collision>
  </link>
  <joint
    name="cam_link1_to_link2"
    type="revolute">
    <origin
      xyz="0 0 0"
      rpy="0 0 0" />
    <parent
      link="cam_link1" />
    <child
      link="cam_link2" />
    <axis
      xyz="0 0 0" />
    <limit
      lower="0"
      upper="0"
      effort="0"
      velocity="0" />
  </joint>
  <link
    name="cam_bracket">
    <inertial>
      <origin
        xyz="-9.7578E-18 0.022518 -0.019"
        rpy="0 0 0" />
      <mass
        value="0.022031" />
      <inertia
        ixx="1.551E-05"
        ixy="8.9796E-22"
        ixz="-3.0606E-22"
        iyy="1.5937E-05"
        iyz="-3.2234E-20"
        izz="1.3846E-06" />
    </inertial>
    <visual>
      <origin
        xyz="0 0 0"
        rpy="0 0 0" />
      <geometry>
        <mesh
          filename="file://$(find ssmm_robot)/meshes/cam_bracket.STL" />
      </geometry>
      <material
        name="">
        <color
          rgba="0.75294 0.75294 0.75294 1" />
      </material>
    </visual>
    <collision>
      <origin
        xyz="0 0 0"
        rpy="0 0 0" />
      <geometry>
        <mesh
          filename="file://$(find ssmm_robot)/meshes/cam_bracket.STL" />
      </geometry>
    </collision>
  </link>
  <joint
    name="link2_to_cam_bracket"
    type="revolute">
    <origin
      xyz="0 0.019 0.0421"
      rpy="1.5708 0 -3.1416" />
    <parent
      link="cam_link2" />
    <child
      link="cam_bracket" />
    <axis
      xyz="0 0 0" />
    <limit
      lower="0"
      upper="0"
      effort="0"
      velocity="0" />
  </joint>
  <link
    name="cam">
    <inertial>
      <origin
        xyz="0.00086722 -0.00012728 -0.0054866"
        rpy="0 0 0" />
      <mass
        value="0.015644" />
      <inertia
        ixx="1.6168E-06"
        ixy="1.9328E-07"
        ixz="-1.0388E-08"
        iyy="1.9717E-05"
        iyz="3.3551E-10"
        izz="2.1037E-05" />
    </inertial>
    <visual>
      <origin
        xyz="0 0 0"
        rpy="0 0 0" />
      <geometry>
        <mesh
          filename="file://$(find ssmm_robot)/meshes/cam.STL" />
      </geometry>
      <material
        name="">
        <color
          rgba="0.75294 0.75294 0.75294 1" />
      </material>
    </visual>
    <collision>
      <origin
        xyz="0 0 0"
        rpy="0 0 0" />
      <geometry>
        <mesh
          filename="file://$(find ssmm_robot)/meshes/cam.STL" />
      </geometry>
    </collision>
  </link>
  <joint
    name="bracket_to_cam"
    type="fixed">
    <origin
      xyz="0 0.0559 -0.019"
      rpy="-1.5708 -1.5598 0" />
    <parent
      link="cam_bracket" />
    <child
      link="cam" />
    <axis
      xyz="0 0 0" />
  </joint> -->
</robot>