<?xml version="1.0"?>
<robot xmlns:xacro="http://www.ros.org/wiki/xacro">

  <xacro:macro name="ssmm_robot" params="prefix">

  <link name="${prefix}base_link">
    <inertial>
      <origin xyz="0.00586310715881636 0.0007562083206322438 0.053945075216020856" rpy="0 0 0"/>
      <mass value="17.871899834134002"/>
      <inertia ixx="0.211334" iyy="0.283613" izz="0.411846" ixy="0.001619" iyz="-0.000758" ixz="-0.003467"/>
    </inertial>
    <visual>
      <origin xyz="0 0 0" rpy="0 0 0"/>
      <geometry>
        <mesh filename="file://$(find ssmm_robot_description)/meshes/base_link.stl" scale="0.001 0.001 0.001"/>
      </geometry>
      <material name="grey"/>
    </visual>
    <collision>
      <origin xyz="0 0 0" rpy="0 0 0"/>
      <geometry>
        <mesh filename="file://$(find ssmm_robot_description)/meshes/base_link.stl" scale="0.001 0.001 0.001"/>
      </geometry>
    </collision>
  </link>

  <link name="${prefix}right_wheel_1_1_1">
    <inertial>
      <origin xyz="5.182139913156858e-07 -0.016701855614142308 1.6426189841656225e-06" rpy="0 0 0"/>
      <mass value="0.9090455014442181"/>
      <inertia ixx="0.000439" iyy="0.000806" izz="0.000439" ixy="-0.0" iyz="-0.0" ixz="0.0"/>
    </inertial>
    <visual>
      <origin xyz="-0.1065 0.167 -0.022" rpy="0 0 0"/>
      <geometry>
        <mesh filename="file://$(find ssmm_robot_description)/meshes/right_wheel_1_1_1.stl" scale="0.001 0.001 0.001"/>
      </geometry>
      <material name="blue"/>
    </visual>
    <collision>
      <origin xyz="-0.1065 0.167 -0.022" rpy="0 0 0"/>
      <geometry>
        <mesh filename="file://$(find ssmm_robot_description)/meshes/right_wheel_1_1_1.stl" scale="0.001 0.001 0.001"/>
      </geometry>
    </collision>
  </link>

  <link name="${prefix}left_wheel_1_1_1">
    <inertial>
      <origin xyz="-1.7220956169961e-06 0.01670185561413512 -3.3626965947886056e-08" rpy="0 0 0"/>
      <mass value="0.9090455014442448"/>
      <inertia ixx="0.000439" iyy="0.000806" izz="0.000439" ixy="-0.0" iyz="-0.0" ixz="0.0"/>
    </inertial>
    <visual>
      <origin xyz="-0.1065 -0.167 -0.022" rpy="0 0 0"/>
      <geometry>
        <mesh filename="file://$(find ssmm_robot_description)/meshes/left_wheel_1_1_1.stl" scale="0.001 0.001 0.001"/>
      </geometry>
      <material name="blue"/>
    </visual>
    <collision>
      <origin xyz="-0.1065 -0.167 -0.022" rpy="0 0 0"/>
      <geometry>
        <mesh filename="file://$(find ssmm_robot_description)/meshes/left_wheel_1_1_1.stl" scale="0.001 0.001 0.001"/>
      </geometry>
    </collision>
  </link>

  <link name="${prefix}link1_1_1_1">
    <inertial>
      <origin xyz="0.04033139479614735 -0.01812836601370036 0.6633070119623178" rpy="0 0 0"/>
      <mass value="37.96782093256132"/>
      <inertia ixx="7.154037" iyy="7.147728" izz="0.104871" ixy="-0.002741" iyz="0.009354" ixz="0.043125"/>
    </inertial>
    <visual>
      <origin xyz="0.162 -0.0 -0.008" rpy="0 0 0"/>
      <geometry>
        <mesh filename="file://$(find ssmm_robot_description)/meshes/link1_1_1_1.stl" scale="0.001 0.001 0.001"/>
      </geometry>
      <material name="Steel-Satin"/>
    </visual>
    <collision>
      <origin xyz="0.162 -0.0 -0.008" rpy="0 0 0"/>
      <geometry>
        <mesh filename="file://$(find ssmm_robot_description)/meshes/link1_1_1_1.stl" scale="0.001 0.001 0.001"/>
      </geometry>
    </collision>
  </link>

  <link name="${prefix}link2_1_1_1">
    <inertial>
      <origin xyz="0.21213379169802077 0.00023867661354338987 0.009055011543400937" rpy="0 0 0"/>
      <mass value="4.29572859245966"/>
      <inertia ixx="0.004629" iyy="0.122353" izz="0.12256" ixy="-0.008336" iyz="0.001047" ixz="0.003262"/>
    </inertial>
    <visual>
      <origin xyz="0.120727 0.0265 -0.688" rpy="0 0 0"/>
      <geometry>
        <mesh filename="file://$(find ssmm_robot_description)/meshes/link2_1_1_1.stl" scale="0.001 0.001 0.001"/>
      </geometry>
      <material name="Steel-Satin"/>
    </visual>
    <collision>
      <origin xyz="0.120727 0.0265 -0.688" rpy="0 0 0"/>
      <geometry>
        <mesh filename="file://$(find ssmm_robot_description)/meshes/link2_1_1_1.stl" scale="0.001 0.001 0.001"/>
      </geometry>
    </collision>
  </link>

  <link name="${prefix}link3_1_1_1">
    <inertial>
      <origin xyz="0.24428083825859598 0.0005100421525429302 -0.0017404596681788176" rpy="0 0 0"/>
      <mass value="1.52991351104183"/>
      <inertia ixx="0.001243" iyy="0.039865" izz="0.040771" ixy="-0.000146" iyz="3e-06" ixz="0.00032"/>
    </inertial>
    <visual>
      <origin xyz="-0.165414 0.012348 -0.7043" rpy="0 0 0"/>
      <geometry>
        <mesh filename="file://$(find ssmm_robot_description)/meshes/link3_1_1_1.stl" scale="0.001 0.001 0.001"/>
      </geometry>
      <material name="Steel-Satin"/>
    </visual>
    <collision>
      <origin xyz="-0.165414 0.012348 -0.7043" rpy="0 0 0"/>
      <geometry>
        <mesh filename="file://$(find ssmm_robot_description)/meshes/link3_1_1_1.stl" scale="0.001 0.001 0.001"/>
      </geometry>
    </collision>
  </link>

  <link name="${prefix}EE_1_1_1">
    <inertial>
      <origin xyz="0.051220770854960795 -0.009976357636134515 0.0006719880832956049" rpy="0 0 0"/>
      <mass value="1.0983178592962715"/>
      <inertia ixx="0.000713" iyy="0.001168" izz="0.001473" ixy="-4.5e-05" iyz="3.7e-05" ixz="3.1e-05"/>
    </inertial>
    <visual>
      <origin xyz="-0.583914 0.011448 -0.7103" rpy="0 0 0"/>
      <geometry>
        <mesh filename="file://$(find ssmm_robot_description)/meshes/EE_1_1_1.stl" scale="0.001 0.001 0.001"/>
      </geometry>
      <material name="black"/>
    </visual>
    <collision>
      <origin xyz="-0.583914 0.011448 -0.7103" rpy="0 0 0"/>
      <geometry>
        <mesh filename="file://$(find ssmm_robot_description)/meshes/EE_1_1_1.stl" scale="0.001 0.001 0.001"/>
      </geometry>
    </collision>
  </link>

  <link name="${prefix}finger_1_1_1">
    <inertial>
      <origin xyz="-0.006452286139622898 0.0024332490706478697 -0.004356053771926716" rpy="0 0 0"/>
      <mass value="0.06862731061297074"/>
      <inertia ixx="1.3e-05" iyy="7e-06" izz="1.5e-05" ixy="-2e-06" iyz="3e-06" ixz="2e-06"/>
    </inertial>
    <visual>
      <origin xyz="-0.678014 0.010517 -0.724805" rpy="0 0 0"/>
      <geometry>
        <mesh filename="file://$(find ssmm_robot_description)/meshes/finger_1_1_1.stl" scale="0.001 0.001 0.001"/>
      </geometry>
      <material name="Steel-Satin"/>
    </visual>
    <collision>
      <origin xyz="-0.678014 0.010517 -0.724805" rpy="0 0 0"/>
      <geometry>
        <mesh filename="file://$(find ssmm_robot_description)/meshes/finger_1_1_1.stl" scale="0.001 0.001 0.001"/>
      </geometry>
    </collision>
  </link>

  <link name="${prefix}lidar_1_1_1">
    <inertial>
      <origin xyz="-0.021844567669604034 0.020828034338592448 0.018471283341560632" rpy="0 0 0"/>
      <mass value="1.2417406970778717"/>
      <inertia ixx="0.00057" iyy="0.000571" izz="0.000824" ixy="0.0" iyz="0.0" ixz="1.4e-05"/>
    </inertial>
    <visual>
      <origin xyz="-0.12286 0.02086 -0.114" rpy="0 0 0"/>
      <geometry>
        <mesh filename="file://$(find ssmm_robot_description)/meshes/lidar_1_1_1.stl" scale="0.001 0.001 0.001"/>
      </geometry>
      <material name="blue"/>
    </visual>
    <collision>
      <origin xyz="-0.12286 0.02086 -0.114" rpy="0 0 0"/>
      <geometry>
        <mesh filename="file://$(find ssmm_robot_description)/meshes/lidar_1_1_1.stl" scale="0.001 0.001 0.001"/>
      </geometry>
    </collision>
  </link>

  <link name="${prefix}cam_link1_1_1_1">
    <inertial>
      <origin xyz="-0.010499995355935042 0.016926202529021217 -0.019834928378613448" rpy="0 0 0"/>
      <mass value="0.483298401932533"/>
      <inertia ixx="0.000157" iyy="0.000115" izz="0.000146" ixy="0.0" iyz="1e-06" ixz="-0.0"/>
    </inertial>
    <visual>
      <origin xyz="-0.01 0.0485 -1.368" rpy="0 0 0"/>
      <geometry>
        <mesh filename="file://$(find ssmm_robot_description)/meshes/cam_link1_1_1_1.stl" scale="0.001 0.001 0.001"/>
      </geometry>
      <material name="black"/>
    </visual>
    <collision>
      <origin xyz="-0.01 0.0485 -1.368" rpy="0 0 0"/>
      <geometry>
        <mesh filename="file://$(find ssmm_robot_description)/meshes/cam_link1_1_1_1.stl" scale="0.001 0.001 0.001"/>
      </geometry>
    </collision>
  </link>

  <link name="${prefix}cam_link2_1_1_1">
    <inertial>
      <origin xyz="-9.170244398455933e-05 -0.0003016447304857936 -0.025126141572863192" rpy="0 0 0"/>
      <mass value="0.4268660964633632"/>
      <inertia ixx="0.000143" iyy="0.000138" izz="8e-05" ixy="-2e-06" iyz="-1e-06" ixz="-0.0"/>
    </inertial>
    <visual>
      <origin xyz="0.0005 0.02 -1.3255" rpy="0 0 0"/>
      <geometry>
        <mesh filename="file://$(find ssmm_robot_description)/meshes/cam_link2_1_1_1.stl" scale="0.001 0.001 0.001"/>
      </geometry>
      <material name="black"/>
    </visual>
    <collision>
      <origin xyz="0.0005 0.02 -1.3255" rpy="0 0 0"/>
      <geometry>
        <mesh filename="file://$(find ssmm_robot_description)/meshes/cam_link2_1_1_1.stl" scale="0.001 0.001 0.001"/>
      </geometry>
    </collision>
  </link>

  <link name="${prefix}realsense_1_1_1">
    <inertial>
      <origin xyz="0.005530128787720442 0.018206480761294087 -0.03227784127752242" rpy="0 0 0"/>
      <mass value="0.2684626559786029"/>
      <inertia ixx="0.000284" iyy="9.3e-05" izz="0.000266" ixy="-6.4e-05" iyz="0.0" ixz="0.0"/>
    </inertial>
    <visual>
      <origin xyz="0.006027 0.038178 -1.2845" rpy="0 0 0"/>
      <geometry>
        <mesh filename="file://$(find ssmm_robot_description)/meshes/realsense_1_1_1.stl" scale="0.001 0.001 0.001"/>
      </geometry>
      <material name="grey"/>
    </visual>
    <collision>
      <origin xyz="0.006027 0.038178 -1.2845" rpy="0 0 0"/>
      <geometry>
        <mesh filename="file://$(find ssmm_robot_description)/meshes/realsense_1_1_1.stl" scale="0.001 0.001 0.001"/>
      </geometry>
    </collision>
  </link>

  <joint name="${prefix}base_to_rw" type="continuous">
    <origin xyz="0.1065 -0.167 0.022" rpy="0 0 0"/>
    <parent link="base_link"/>
    <child link="right_wheel_1_1_1"/>
    <axis xyz="0.0 1.0 0.0"/>
  </joint>

  <joint name="${prefix}base_to_lw" type="continuous">
    <origin xyz="0.1065 0.167 0.022" rpy="0 0 0"/>
    <parent link="base_link"/>
    <child link="left_wheel_1_1_1"/>
    <axis xyz="-0.0 -1.0 -0.0"/>
  </joint>

  <joint name="${prefix}base_to_link1" type="fixed">
    <origin xyz="-0.162 0.0 0.008" rpy="0 0 0"/>
    <parent link="base_link"/>
    <child link="link1_1_1_1"/>
  </joint>

  <joint name="${prefix}link1_to_link2" type="prismatic">
    <origin xyz="0.041273 -0.0265 0.68" rpy="0 0 0"/>
    <parent link="link1_1_1_1"/>
    <child link="link2_1_1_1"/>
    <axis xyz="-0.0 -0.0 -1.0"/>
    <limit upper="0.0" lower="0.0" effort="100" velocity="100"/>
  </joint>

  <joint name="${prefix}link2_to_link3" type="prismatic">
    <origin xyz="0.286141 0.014152 0.0163" rpy="0 0 0"/>
    <parent link="link2_1_1_1"/>
    <child link="link3_1_1_1"/>
    <axis xyz="-1.0 0.0 -0.0"/>
    <limit upper="0.0" lower="0.0" effort="100" velocity="100"/>
  </joint>

  <joint name="${prefix}link3_to_ee" type="continuous">
    <origin xyz="0.4185 0.0009 0.006" rpy="0 0 0"/>
    <parent link="link3_1_1_1"/>
    <child link="EE_1_1_1"/>
    <axis xyz="1.0 -0.0 0.0"/>
  </joint>

  <joint name="${prefix}ee_to_finger" type="prismatic">
    <origin xyz="0.0941 0.000931 0.014505" rpy="0 0 0"/>
    <parent link="EE_1_1_1"/>
    <child link="finger_1_1_1"/>
    <axis xyz="-0.0 -0.991167 0.132623"/>
    <limit upper="0.0" lower="0.0" effort="100" velocity="100"/>
  </joint>

  <joint name="${prefix}base_to_lidar" type="fixed">
    <origin xyz="0.12286 -0.02086 0.114" rpy="0 0 0"/>
    <parent link="base_link"/>
    <child link="lidar_1_1_1"/>
  </joint>

  <joint name="${prefix}link1_to_cm1" type="fixed">
    <origin xyz="0.172 -0.0485 1.36" rpy="0 0 0"/>
    <parent link="link1_1_1_1"/>
    <child link="cam_link1_1_1_1"/>
  </joint>

  <joint name="${prefix}cm1_to_cm2" type="continuous">
    <origin xyz="-0.0105 0.0285 -0.0425" rpy="0 0 0"/>
    <parent link="cam_link1_1_1_1"/>
    <child link="cam_link2_1_1_1"/>
    <axis xyz="0.0 -0.0 -1.0"/>
  </joint>

  <joint name="${prefix}cm2_to_cam" type="continuous">
    <origin xyz="-0.005527 -0.018178 -0.041" rpy="0 0 0"/>
    <parent link="cam_link2_1_1_1"/>
    <child link="realsense_1_1_1"/>
    <axis xyz="-0.29088 -0.95676 0.0"/>
  </joint>
  
  </xacro:macro>

</robot>
